Traceback (most recent call last):
  File "C:\anaconda3\envs\abe_website\lib\site-packages\jupyter_cache\executors\utils.py", line 64, in single_nb_execution
    **kwargs,
  File "C:\anaconda3\envs\abe_website\lib\site-packages\nbclient\client.py", line 1204, in execute
    return NotebookClient(nb=nb, resources=resources, km=km, **kwargs).execute()
  File "C:\anaconda3\envs\abe_website\lib\site-packages\nbclient\util.py", line 84, in wrapped
    return just_run(coro(*args, **kwargs))
  File "C:\anaconda3\envs\abe_website\lib\site-packages\nbclient\util.py", line 62, in just_run
    return loop.run_until_complete(coro)
  File "C:\anaconda3\envs\abe_website\lib\asyncio\base_events.py", line 587, in run_until_complete
    return future.result()
  File "C:\anaconda3\envs\abe_website\lib\site-packages\nbclient\client.py", line 664, in async_execute
    cell, index, execution_count=self.code_cells_executed + 1
  File "C:\anaconda3\envs\abe_website\lib\site-packages\nbclient\client.py", line 965, in async_execute_cell
    await self._check_raise_for_error(cell, cell_index, exec_reply)
  File "C:\anaconda3\envs\abe_website\lib\site-packages\nbclient\client.py", line 862, in _check_raise_for_error
    raise CellExecutionError.from_cell_and_msg(cell, exec_reply_content)
nbclient.exceptions.CellExecutionError: An error occurred while executing the following cell:
------------------
import csv
# Opening a CSV file for appending
file_csv = r'docs/_assets/myfile/data.csv'
with open(file_csv, 'a', newline='') as file:
    writer = csv.writer(file)

    # Appending additional data rows
    writer.writerow(['Bob', 35, 'Australia'])
    writer.writerow(['Emma', 28, 'UK'])

# Opening a CSV file for reading
with open(file_csv, 'r') as file:
    reader = csv.reader(file)

    # Reading and printing all rows
    for row in reader:
        print(row)
------------------

[1;31m---------------------------------------------------------------------------[0m
[1;31mFileNotFoundError[0m                         Traceback (most recent call last)
[1;32m~\AppData\Local\Temp\ipykernel_40436\3859263647.py[0m in [0;36m<module>[1;34m[0m
[0;32m      2[0m [1;31m# Opening a CSV file for appending[0m[1;33m[0m[1;33m[0m[1;33m[0m[0m
[0;32m      3[0m [0mfile_csv[0m [1;33m=[0m [1;34mr'docs/_assets/myfile/data.csv'[0m[1;33m[0m[1;33m[0m[0m
[1;32m----> 4[1;33m [1;32mwith[0m [0mopen[0m[1;33m([0m[0mfile_csv[0m[1;33m,[0m [1;34m'a'[0m[1;33m,[0m [0mnewline[0m[1;33m=[0m[1;34m''[0m[1;33m)[0m [1;32mas[0m [0mfile[0m[1;33m:[0m[1;33m[0m[1;33m[0m[0m
[0m[0;32m      5[0m     [0mwriter[0m [1;33m=[0m [0mcsv[0m[1;33m.[0m[0mwriter[0m[1;33m([0m[0mfile[0m[1;33m)[0m[1;33m[0m[1;33m[0m[0m
[0;32m      6[0m [1;33m[0m[0m

[1;31mFileNotFoundError[0m: [Errno 2] No such file or directory: 'docs/_assets/myfile/data.csv'
FileNotFoundError: [Errno 2] No such file or directory: 'docs/_assets/myfile/data.csv'

