Traceback (most recent call last):
  File "C:\anaconda3\envs\abe_website\lib\site-packages\jupyter_cache\executors\utils.py", line 64, in single_nb_execution
    **kwargs,
  File "C:\anaconda3\envs\abe_website\lib\site-packages\nbclient\client.py", line 1204, in execute
    return NotebookClient(nb=nb, resources=resources, km=km, **kwargs).execute()
  File "C:\anaconda3\envs\abe_website\lib\site-packages\nbclient\util.py", line 84, in wrapped
    return just_run(coro(*args, **kwargs))
  File "C:\anaconda3\envs\abe_website\lib\site-packages\nbclient\util.py", line 62, in just_run
    return loop.run_until_complete(coro)
  File "C:\anaconda3\envs\abe_website\lib\asyncio\base_events.py", line 587, in run_until_complete
    return future.result()
  File "C:\anaconda3\envs\abe_website\lib\site-packages\nbclient\client.py", line 664, in async_execute
    cell, index, execution_count=self.code_cells_executed + 1
  File "C:\anaconda3\envs\abe_website\lib\site-packages\nbclient\client.py", line 965, in async_execute_cell
    await self._check_raise_for_error(cell, cell_index, exec_reply)
  File "C:\anaconda3\envs\abe_website\lib\site-packages\nbclient\client.py", line 862, in _check_raise_for_error
    raise CellExecutionError.from_cell_and_msg(cell, exec_reply_content)
nbclient.exceptions.CellExecutionError: An error occurred while executing the following cell:
------------------
# define a class
class Student:
    # define an attribute
    student_id = vsm

# create two objects of the Employee class
Student1 = Student()
Student2 = Student()

# access attributes using Student1
Student1.student_id = 'test_2@msstate.edu'
print(f"Student ID: {Student1.student_id}")

# access attributes using Student2
Student2.student_id = 'test_2@msstate.edu'
print(f"Employee ID: {Student2.student_id}")
------------------

[1;31m---------------------------------------------------------------------------[0m
[1;31mNameError[0m                                 Traceback (most recent call last)
[1;32m~\AppData\Local\Temp\ipykernel_86636\2754255128.py[0m in [0;36m<module>[1;34m[0m
[0;32m      1[0m [1;31m# define a class[0m[1;33m[0m[1;33m[0m[1;33m[0m[0m
[1;32m----> 2[1;33m [1;32mclass[0m [0mStudent[0m[1;33m:[0m[1;33m[0m[1;33m[0m[0m
[0m[0;32m      3[0m     [1;31m# define an attribute[0m[1;33m[0m[1;33m[0m[1;33m[0m[0m
[0;32m      4[0m     [0mstudent_id[0m [1;33m=[0m [0mvsm[0m[1;33m[0m[1;33m[0m[0m
[0;32m      5[0m [1;33m[0m[0m

[1;32m~\AppData\Local\Temp\ipykernel_86636\2754255128.py[0m in [0;36mStudent[1;34m()[0m
[0;32m      2[0m [1;32mclass[0m [0mStudent[0m[1;33m:[0m[1;33m[0m[1;33m[0m[0m
[0;32m      3[0m     [1;31m# define an attribute[0m[1;33m[0m[1;33m[0m[1;33m[0m[0m
[1;32m----> 4[1;33m     [0mstudent_id[0m [1;33m=[0m [0mvsm[0m[1;33m[0m[1;33m[0m[0m
[0m[0;32m      5[0m [1;33m[0m[0m
[0;32m      6[0m [1;31m# create two objects of the Employee class[0m[1;33m[0m[1;33m[0m[1;33m[0m[0m

[1;31mNameError[0m: name 'vsm' is not defined
NameError: name 'vsm' is not defined

