Traceback (most recent call last):
  File "C:\anaconda3\envs\abe_website\lib\site-packages\jupyter_cache\executors\utils.py", line 64, in single_nb_execution
    **kwargs,
  File "C:\anaconda3\envs\abe_website\lib\site-packages\nbclient\client.py", line 1204, in execute
    return NotebookClient(nb=nb, resources=resources, km=km, **kwargs).execute()
  File "C:\anaconda3\envs\abe_website\lib\site-packages\nbclient\util.py", line 84, in wrapped
    return just_run(coro(*args, **kwargs))
  File "C:\anaconda3\envs\abe_website\lib\site-packages\nbclient\util.py", line 62, in just_run
    return loop.run_until_complete(coro)
  File "C:\anaconda3\envs\abe_website\lib\asyncio\base_events.py", line 587, in run_until_complete
    return future.result()
  File "C:\anaconda3\envs\abe_website\lib\site-packages\nbclient\client.py", line 664, in async_execute
    cell, index, execution_count=self.code_cells_executed + 1
  File "C:\anaconda3\envs\abe_website\lib\site-packages\nbclient\client.py", line 965, in async_execute_cell
    await self._check_raise_for_error(cell, cell_index, exec_reply)
  File "C:\anaconda3\envs\abe_website\lib\site-packages\nbclient\client.py", line 862, in _check_raise_for_error
    raise CellExecutionError.from_cell_and_msg(cell, exec_reply_content)
nbclient.exceptions.CellExecutionError: An error occurred while executing the following cell:
------------------
import sys

if len(sys.argv) != 4:
    print("Usage: python myscript.py <num1> <operator> <num2>")
    sys.exit()

num1 = float(sys.argv[1])
operator = sys.argv[2]
num2 = float(sys.argv[3])

if operator == "+":
    result = num1 + num2
elif operator == "-":
    result = num1 - num2
elif operator == "*":
    result = num1 * num2
elif operator == "/":
    result = num1 / num2
else:
    print("Invalid operator provided.")
    sys.exit()

print(f"{num1} {operator} {num2} = {result}")
------------------

[1;31m---------------------------------------------------------------------------[0m
[1;31mValueError[0m                                Traceback (most recent call last)
[1;32m~\AppData\Local\Temp\ipykernel_36000\540897815.py[0m in [0;36m<module>[1;34m[0m
[0;32m      5[0m     [0msys[0m[1;33m.[0m[0mexit[0m[1;33m([0m[1;33m)[0m[1;33m[0m[1;33m[0m[0m
[0;32m      6[0m [1;33m[0m[0m
[1;32m----> 7[1;33m [0mnum1[0m [1;33m=[0m [0mfloat[0m[1;33m([0m[0msys[0m[1;33m.[0m[0margv[0m[1;33m[[0m[1;36m1[0m[1;33m][0m[1;33m)[0m[1;33m[0m[1;33m[0m[0m
[0m[0;32m      8[0m [0moperator[0m [1;33m=[0m [0msys[0m[1;33m.[0m[0margv[0m[1;33m[[0m[1;36m2[0m[1;33m][0m[1;33m[0m[1;33m[0m[0m
[0;32m      9[0m [0mnum2[0m [1;33m=[0m [0mfloat[0m[1;33m([0m[0msys[0m[1;33m.[0m[0margv[0m[1;33m[[0m[1;36m3[0m[1;33m][0m[1;33m)[0m[1;33m[0m[1;33m[0m[0m

[1;31mValueError[0m: could not convert string to float: '-f'
ValueError: could not convert string to float: '-f'

